Workbook
Name Slicer_Channel: #N/A
Name Slicer_Country: #N/A
Name Slicer_Month: #N/A
Name Slicer_Region: #N/A
Name Slicer_Salesperson: #N/A

Sheet Data
A1: OrderID | B1: OrderDate | C1: RequiredDate | D1: Region | E1: Country | F1: City | G1: CustomerSegment | H1: Channel | I1: Salesperson | J1: ProductCategory | K1: SKU | L1: UnitCost | M1: UnitPrice | N1: DiscountPct | O1: Quantity
A2: ORD-2024-275203 | B2: 45362 | C2: 45388 | D2: Africa | E2: Kenya | F2: Kisumu | G2: Corporate | H2: Retail | I2: C. Otieno | J2: Components | K2: CMP-8270 | L2: 279.24 | M2: 608.9 | N2: 0.112 | O2: 9
A3: ORD-2024-358795 | B3: 45588 | C3: 45587 | D3: Africa | E3: Nigeria | F3: Port Harcourt | G3: Education | H3: Online | I3: J. Njeri | J3: Printers | K3: PRN-9322 | L3: 1084.39 | M3: 759.33 | N3: 0.237 | O3: 31
A4: ORD-2023-373538 | B4: 44985 | C4: 45010 | D4: Africa | E4: Kenya | F4: Nairobi | G4: Corporate | H4: Retail | I4: I. Johnson | J4: Networking | K4: NET-9666 | L4: 1460.76 | M4: -30.66 | N4: 0.131 | O4: 12
A5: ORD-2025-168148 | B5: 45745 | C5: 45749 | D5: Africa | E5: Nigeria | F5: Lagos | G5: Non-Profit | H5: Marketplace | I5: G. Dubois | J5: Phones | K5: PHN-4556 | L5: 259.93 | M5: 255.94 | N5: 0.072 | O5: 22
A6: ORD-2023-824839 | B6: 45266 | C6: 45291 | D6: Asia | E6: Japan | F6: Osaka | G6: Consumer | H6: Retail | I6: L. Okafor | J6: Printers | K6: PRN-8041 | L6: 663.03 | M6: 813.51 | N6: 0.102 | O6: 15
A7: ORD-2023-723587 | B7: 44928 | C7: 44931 | D7: Americas | E7: Canada | F7: Toronto | G7: Corporate | H7: Distributor | I7: B. Chen | J7: Laptops | K7: LAP-8555 | L7: 315.87 | M7: 591.68 | N7: 0 | O7: 7
A8: ORD-2024-336584 | B8: 45653 | C8: 45671 | D8: Asia | E8: India | F8: Bengaluru | G8: Small Business | H8: Marketplace | I8: E. Garcia | J8: Monitors | K8: MON-8629 | L8: 586.07 | M8: 845.97 | N8: 0.147 | O8: 4
A9: ORD-2023-112666 | B9: 44941 | C9: 44939 | D9: Africa | E9: Nigeria | F9: Abuja | G9: Education | H9: Online | I9: O. Wang | J9: Printers | K9: PRN-6276 | L9: 28.38 | M9: 47.22 | N9: 0.194 | O9: 18
A10: ORD-2024-589570 | B10: 45416 | C10: 45441 | D10: Africa | E10: Nigeria | F10: Abuja | G10: Non-Profit | H10: Marketplace | I10: O. Wang | J10: Monitors | K10: MON-6892 | L10: 1295.34 | M10: 2530.81 | N10: 0.031 | O10: 6
A11: ORD-2025-997421 | B11: 45798 | C11: 45817 | D11: Americas | E11: Brazil | F11: São Paulo | G11: Non-Profit | H11: Online | I11: A. Patel | J11: Components | K11: CMP-3731 | L11: 1331.38 | M11: 2309.56 | N11: 0.149 | O11: 31
A12: ORD-2024-210687 | B12: 45319 | C12: 45331 | D12: Europe | E12: Germany | F12: Berlin | G12: Corporate | H12: Online | I12: G. Dubois | J12: Accessories | K12: ACC-7938 | L12: 644.17 | M12: 700.12 | N12: 0.006 | O12: 23
A13: ORD-2025-515515 | B13: 45660 | C13: 45680 | D13: Asia | E13: Japan | F13: Osaka | G13: Corporate | H13: Distributor | I13: F. Müller | J13: Phones | K13: PHN-7019 | L13: 908.6 | M13: 691.37 | N13: 0.25 | O13: 20
... A34: ORD-2025-474710 | B34: 45862 | C34: 45875 | D34: Africa | E34: South Africa | F34: Johannesburg | G34: Education | H34: Marketplace | I34: D. Smith | J34: Networking | K34: NET-7966 | L34: 1463.9 | M34: 2633.02 | N34: 0.084 | O34: 4
A35: ORD-2024-629525 | B35: 45400 | C35: 45420 | D35: Europe | E35: United Kingdom | F35: London | G35: Non-Profit | I35: D. Smith | J35: Laptops | K35: LAP-9932 | L35: 645.33 | M35: 1321.85 | N35: 0 | O35: 10
A36: ORD-2024-167215 | B36: 45527 | C36: 45525 | D36: Africa | E36: South Africa | F36: Johannesburg | G36: Education | H36: Retail | I36: E. Garcia | J36: Components | K36: CMP-1559 | L36: 1432.52 | M36: 3036.87 | N36: 0 | O36: 9
A37: ORD-2023-864121 | B37: 45012 | C37: 45038 | D37: Asia | E37: India | F37: Delhi | G37: Non-Profit | H37: Marketplace | I37: J. Njeri | J37: Printers | K37: PRN-4506 | L37: 178.53 | M37: 199.37 | N37: 0.101 | O37: 37
A38: ORD-2024-692673 | B38: 45358 | C38: 45376 | D38: Europe | E38: Germany | F38: Munich | G38: Corporate | H38: Online | I38: B. Chen | J38: Components | K38: CMP-7617 | L38: 712.84 | M38: 927.51 | N38: 0.243 | O38: 27
A39: ORD-2025-718992 | B39: 45832 | C39: 45848 | D39: Asia | E39: China | F39: Shanghai | G39: Enterprise | H39: Direct | I39: N. Brown | J39: Components | K39: CMP-8390 | L39: 757.19 | M39: 1735.41 | N39: 0.136 | O39: 8
A40: ORD-2024-599522 | B40: 45401 | C40: 45418 | D40: Africa | E40: Nigeria | F40: Port Harcourt | G40: Non-Profit | H40: Online | I40: A. Patel | J40: Printers | K40: PRN-7303 | L40: 865.33 | M40: 1395.64 | N40: 0.175 | O40: 13
A41: ORD-2023-651638 | B41: 45094 | C41: 45101 | D41: Americas | E41: USA | F41: San Francisco | G41: Corporate | H41: Retail | I41: I. Johnson | J41: Printers | K41: PRN-6536 | L41: 313.99 | M41: 454.42 | N41: 0.129 | O41: 9
A42: ORD-2024-635626 | B42: 45531 | C42: 45554 | D42: Europe | E42: Germany | F42: Berlin | G42: Small Business | H42: Direct | I42: D. Smith | J42: Monitors | K42: MON-9967 | L42: 1024.01 | M42: 1580.97 | N42: 0.037 | O42: 27
A43: ORD-2024-296582 | B43: 45302 | C43: 45324 | D43: Africa | E43: South Africa | F43: Durban | G43: Consumer | H43: Online | I43: K. Singh | J43: Networking | K43: NET-1412 | L43: 1206.2 | M43: 1759.79 | N43: 0 | O43: 6
A44: ORD-2024-998320 | B44: 45590 | C44: 45610 | D44: Africa | E44: Kenya | F44: Mombasa | G44: Corporate | H44: Direct | I44: H. Kim | J44: Printers | K44: PRN-3143 | L44: 1396.48 | M44: 3204.5 | N44: 0.318 | O44: 14
A45: ORD-2025-820255 | B45: 45806 | C45: 45828 | D45: Europe | E45: Germany | F45: Berlin | G45: Corporate | H45: Direct | I45: A. Patel | J45: Printers | K45: PRN-9787 | L45: 483.47 | M45: 1135.43 | N45: 0.146 | O45: 11
A46: ORD-2024-389336 | B46: 45432 | C46: 45445 | D46: Americas | E46: Canada | F46: Vancouver | G46: Enterprise | H46: Marketplace | I46: K. Singh | J46: Components | K46: CMP-5946 | L46: 675.43 | M46: 996.36 | N46: 0.182 | O46: 22
A47: ORD-2023-308124 | B47: 45035 | C47: 45046 | D47: Asia | E47: India | F47: Delhi | G47: Small Business | H47: Retail | I47: A. Patel | J47: Networking | K47: NET-2062 | L47: 826.55 | M47: 1397.05 | N47: 0.169 | O47: 28
... A77: ORD-2023-722117 | B77: 45187 | C77: 45207 | D77: Asia | E77: India | F77: Delhi | G77: Small Business | H77: Direct | I77: B. Chen | J77: Components | K77: CMP-1009 | L77: 825.64 | M77: 1108.43 | N77: 0.114 | O77: 7
A78: ORD-2024-446699 | B78: 45532 | C78: 45560 | D78: Americas | E78: Brazil | F78: Rio de Janeiro | G78: Non-Profit | H78: Online | J78: Accessories | K78: ACC-4490 | L78: 1394.65 | M78: 3144.1 | N78: 0.134 | O78: 13
A79: ORD-2024-451005 | B79: 45473 | C79: 45471 | D79: Americas | E79: Brazil | F79: Rio de Janeiro | G79: Small Business | H79: Direct | I79: L. Okafor | J79: Accessories | K79: ACC-9162 | L79: 1112.98 | M79: 2095.73 | N79: 0.072 | O79: 17
A80: ORD-2023-290279 | B80: 45091 | C80: 45093 | D80: Europe | E80: United Kingdom | F80: Manchester | G80: Non-Profit | H80: Direct | I80: K. Singh | J80: Components | K80: CMP-5820 | L80: 357.36 | M80: 703.62 | N80: 0.257 | O80: 20
A81: ORD-2024-192263 | B81: 45617 | C81: 45647 | D81: Europe | E81: France | F81: Marseille | G81: Small Business | H81: Direct | I81: I. Johnson | J81: Monitors | K81: MON-7943 | L81: 1122.68 | M81: 1997.19 | N81: 0.186 | O81: 3
A82: ORD-2023-159379 | B82: 44965 | C82: 44968 | D82: Africa | E82: South Africa | F82: Cape Town | G82: Corporate | H82: Direct | I82: M. Rossi | J82: Networking | K82: NET-5018 | L82: 1410.05 | M82: 2763.95 | N82: 0.161 | O82: 26
A83: ORD-2023-343322 | B83: 45157 | C83: 45181 | D83: Americas | E83: Canada | F83: Vancouver | G83: Enterprise | H83: Retail | I83: I. Johnson | J83: Printers | K83: PRN-9669 | L83: 1183.95 | M83: 1503.53 | N83: 0.241 | O83: 16
A84: ORD-2025-114382 | B84: 45791 | C84: 45801 | D84: Europe | E84: France | F84: Paris | G84: Small Business | H84: Marketplace | I84: K. Singh | J84: Components | K84: CMP-2865 | L84: 170.39 | M84: 388.04 | N84: 0.084 | O84: 15
A85: ORD-2025-488349 | B85: 45770 | C85: 45769 | D85: Americas | E85: USA | F85: San Francisco | G85: Non-Profit | H85: Distributor | I85: D. Smith | J85: Monitors | K85: MON-3371 | L85: 23.24 | M85: 44.57 | N85: 0.215 | O85: 15
A86: ORD-2025-330203 | B86: 45741 | C86: 45764 | D86: Europe | E86: United Kingdom | F86: London | G86: Consumer | H86: Retail | I86: H. Kim | J86: Networking | K86: NET-7166 | L86: 1421.19 | M86: 1808.26 | N86: 0.104 | O86: 13
A87: ORD-2023-841426 | B87: 45282 | C87: 45283 | D87: Africa | E87: South Africa | F87: Cape Town | G87: Non-Profit | H87: Marketplace | I87: D. Smith | J87: Components | K87: CMP-4531 | L87: 1186.18 | M87: 1285.09 | N87: 0.07 | O87: 11
A88: ORD-2024-594592 | B88: 45388 | C88: 45407 | D88: Asia | E88: China | F88: Shanghai | G88: Corporate | H88: Retail | I88: K. Singh | J88: Components | K88: CMP-8196 | L88: 1366.48 | M88: 1678.14 | N88: 0.154 | O88: 10
A89: ORD-2025-863978 | B89: 45876 | C89: 45888 | D89: Africa | E89: Kenya | F89: Nakuru | G89: Corporate | I89: M. Rossi | J89: Components | K89: CMP-2854 | L89: 601.51 | M89: 679.35 | N89: 0.188 | O89: 3
...

Sheet Staging Table
A1: OrderID | B1: OrderDate | C1: Month | D1: Quarter | E1: RequiredDate | F1: UpdatedRequiredDate | G1: LeadTimeDays | H1: Region | I1: Country | J1: City | K1: CustomerSegment | L1: Channel | M1: Salesperson | N1: ProductCategory | O1: SKU | P1: UnitCost | Q1: UnitPrice | R1: DiscountPct | S1: Disc>30 | T1: Quantity | U1: GrossRevenue | V1: Cost of Goods | W1: Gross Profit | X1: MarginPct | Y1: Price Band | Z1: Met Target | AA1: Disc>20 | AB1: Adjusted Discount% | AC1: Adjusted Unit Cost | AD1: Adjusted Quantity | AE1: Scenario Revenue | AF1: Scenario Profit
A2: ORD-2024-930679 | B2: 45643 | C2: =TEXT(B2,"MMM-YYYY") -> Dec-2024 | D2: ="Q" & ROUNDUP(MONTH(B2)/3,0) & "-" & YEAR(B2) -> Q4-2024 | E2: 45673 | F2: =IF(B2>E2,B2+14,E2) -> 45673 | G2: =F2-B2 -> 30 | H2: Europe | I2: United Kingdom | J2: Manchester | K2: Corporate | L2: Retail | M2: D. Smith | N2: Monitors | O2: MON-4215 | P2: 722.87 | Q2: =((100%-R2)*(P2*T2))/T2 -> 649.13726 | R2: 0.102 | S2: =IF(R2>30,TRUE) -> FALSE | T2: 28 | U2: =(Q2*(100%-R2))*T2 -> 16321.907 | V2: =P2*T2 -> 20240.36 | W2: =U2-V2 -> -3918.4527 | X2: =IF(U2=0,0,W2/U2) -> -0.24007321 | Y2: =IF(Q2<=_xlfn.PERCENTILE.INC($Q$2:$Q$610,0.33),"Low",IF(Q2<=_xlfn.PERCENTILE.INC($Q$2:$Q$610,0.67),"Medium","High")) -> Low | Z2: =IF(G2<=7,"Met","Not Met") -> Not Met | AA2: =IF(R2>20%,"High Discount","Low Discount") -> Low Discount | AB2: =MIN(R2,ControlPanel!$B$5) -> 0.102 | AC2: =P2*(1+ControlPanel!$B$6) -> 759.0135 | AD2: =T2*(1+ControlPanel!$B$7) -> 30.8 | AE2: =(Q2*(100%-AB2)*AD2) -> 17954.098 | AF2: =AE2-(AC2*AD2) -> -5423.5178
A3: ORD-2023-373538 | B3: 44985 | C3: =TEXT(B3,"MMM-YYYY") -> Feb-2023 | D3: ="Q" & ROUNDUP(MONTH(B3)/3,0) & "-" & YEAR(B3) -> Q1-2023 | E3: 45010 | F3: =IF(B3>E3,B3+14,E3) -> 45010 | G3: =F3-B3 -> 25 | H3: Africa | I3: Kenya | J3: Nairobi | K3: Corporate | L3: Retail | M3: I. Johnson | N3: Networking | O3: NET-9666 | P3: 1460.76 | Q3: =((100%-R3)*(P3*T3))/T3 -> 1269.4004 | R3: 0.131 | S3: =IF(R3>30,TRUE) -> FALSE | T3: 12 | U3: =(Q3*(100%-R3))*T3 -> 13237.308 | V3: =P3*T3 -> 17529.12 | W3: =U3-V3 -> -4291.8122 | X3: =IF(U3=0,0,W3/U3) -> -0.32422093 | Y3: =IF(Q3<=_xlfn.PERCENTILE.INC($Q$2:$Q$610,0.33),"Low",IF(Q3<=_xlfn.PERCENTILE.INC($Q$2:$Q$610,0.67),"Medium","High")) -> Medium | Z3: =IF(G3<=7,"Met","Not Met") -> Not Met | AA3: =IF(R3>20%,"High Discount","Low Discount") -> Low Discount | AB3: =MIN(R3,ControlPanel!$B$5) -> 0.131 | AC3: =P3*(1+ControlPanel!$B$6) -> 1533.798 | AD3: =T3*(1+ControlPanel!$B$7) -> 13.2 | AE3: =(Q3*(100%-AB3)*AD3) -> 14561.039 | AF3: =AE3-(AC3*AD3) -> -5685.095
A4: ORD-2025-639542 | B4: 45817 | C4: =TEXT(B4,"MMM-YYYY") -> Jun-2025 | D4: ="Q" & ROUNDUP(MONTH(B4)/3,0) & "-" & YEAR(B4) -> Q2-2025 | E4: 45826 | F4: =IF(B4>E4,B4+14,E4) -> 45826 | G4: =F4-B4 -> 9 | H4: Europe | I4: France | J4: Marseille | K4: Small Business | L4: Marketplace | M4: H. Kim | N4: Accessories | O4: ACC-1770 | P4: 1225.5 | Q4: =((100%-R4)*(P4*T4))/T4 -> 1133.5875 | R4: 0.075 | S4: =IF(R4>30,TRUE) -> FALSE | T4: 56 | U4: =(Q4*(100%-R4))*T4 -> 58719.833 | V4: =P4*T4 -> 68628 | W4: =U4-V4 -> -9908.1675 | X4: =IF(U4=0,0,W4/U4) -> -0.1687363 | Y4: =IF(Q4<=_xlfn.PERCENTILE.INC($Q$2:$Q$610,0.33),"Low",IF(Q4<=_xlfn.PERCENTILE.INC($Q$2:$Q$610,0.67),"Medium","High")) -> Medium | Z4: =IF(G4<=7,"Met","Not Met") -> Not Met | AA4: =IF(R4>20%,"High Discount","Low Discount") -> Low Discount | AB4: =MIN(R4,ControlPanel!$B$5) -> 0.075 | AC4: =P4*(1+ControlPanel!$B$6) -> 1286.775 | AD4: =T4*(1+ControlPanel!$B$7) -> 61.6 | AE4: =(Q4*(100%-AB4)*AD4) -> 64591.816 | AF4: =AE4-(AC4*AD4) -> -14673.524
A5: ORD-2024-207096 | B5: 45377 | C5: =TEXT(B5,"MMM-YYYY") -> Mar-2024 | D5: ="Q" & ROUNDUP(MONTH(B5)/3,0) & "-" & YEAR(B5) -> Q1-2024 | E5: 45387 | F5: =IF(B5>E5,B5+14,E5) -> 45387 | G5: =F5-B5 -> 10 | H5: Americas | I5: USA | J5: Austin | K5: Consumer | L5: Direct | M5: J. Njeri | N5: Monitors | O5: MON-5444 | P5: 5.66 | Q5: 4.22 | R5: 0.119 | S5: =IF(R5>30,TRUE) -> FALSE | T5: 18 | U5: =(Q5*(100%-R5))*T5 -> 66.92076 | V5: =P5*T5 -> 101.88 | W5: =U5-V5 -> -34.95924 | X5: =IF(U5=0,0,W5/U5) -> -0.52239753 | Y5: =IF(Q5<=_xlfn.PERCENTILE.INC($Q$2:$Q$610,0.33),"Low",IF(Q5<=_xlfn.PERCENTILE.INC($Q$2:$Q$610,0.67),"Medium","High")) -> Low | Z5: =IF(G5<=7,"Met","Not Met") -> Not Met | AA5: =IF(R5>20%,"High Discount","Low Discount") -> Low Discount | AB5: =MIN(R5,ControlPanel!$B$5) -> 0.119 | AC5: =P5*(1+ControlPanel!$B$6) -> 5.943 | AD5: =T5*(1+ControlPanel!$B$7) -> 19.8 | AE5: =(Q5*(100%-AB5)*AD5) -> 73.612836 | AF5: =AE5-(AC5*AD5) -> -44.058564
A6: ORD-2024-919471 | B6: 45472 | C6: =TEXT(B6,"MMM-YYYY") -> Jun-2024 | D6: ="Q" & ROUNDUP(MONTH(B6)/3,0) & "-" & YEAR(B6) -> Q2-2024 | E6: 45499 | F6: =IF(B6>E6,B6+14,E6) -> 45499 | G6: =F6-B6 -> 27 | H6: Africa | I6: South Africa | J6: Durban | K6: Enterprise | L6: Distributor | M6: B. Chen | N6: Networking | O6: NET-4241 | P6: 5.36 | Q6: 4.37 | R6: 0.118 | S6: =IF(R6>30,TRUE) -> FALSE | T6: 9 | U6: =(Q6*(100%-R6))*T6 -> 34.68906 | V6: =P6*T6 -> 48.24 | W6: =U6-V6 -> -13.55094 | X6: =IF(U6=0,0,W6/U6) -> -0.39064016 | Y6: =IF(Q6<=_xlfn.PERCENTILE.INC($Q$2:$Q$610,0.33),"Low",IF(Q6<=_xlfn.PERCENTILE.INC($Q$2:$Q$610,0.67),"Medium","High")) -> Low | Z6: =IF(G6<=7,"Met","Not Met") -> Not Met | AA6: =IF(R6>20%,"High Discount","Low Discount") -> Low Discount | AB6: =MIN(R6,ControlPanel!$B$5) -> 0.118 | AC6: =P6*(1+ControlPanel!$B$6) -> 5.628 | AD6: =T6*(1+ControlPanel!$B$7) -> 9.9 | AE6: =(Q6*(100%-AB6)*AD6) -> 38.157966 | AF6: =AE6-(AC6*AD6) -> -17.559234
A7: ORD-2025-667201 | B7: 45915 | C7: =TEXT(B7,"MMM-YYYY") -> Sep-2025 | D7: ="Q" & ROUNDUP(MONTH(B7)/3,0) & "-" & YEAR(B7) -> Q3-2025 | E7: 45918 | F7: =IF(B7>E7,B7+14,E7) -> 45918 | G7: =F7-B7 -> 3 | H7: Americas | I7: Brazil | J7: Rio de Janeiro | K7: Non-Profit | L7: Direct | M7: L. Okafor | N7: Accessories | O7: ACC-6777 | P7: 5.5 | Q7: 5.92 | R7: 0.212 | S7: =IF(R7>30,TRUE) -> FALSE | T7: 4 | U7: =(Q7*(100%-R7))*T7 -> 18.65984 | V7: =P7*T7 -> 22 | W7: =U7-V7 -> -3.34016 | X7: =IF(U7=0,0,W7/U7) -> -0.17900261 | Y7: =IF(Q7<=_xlfn.PERCENTILE.INC($Q$2:$Q$610,0.33),"Low",IF(Q7<=_xlfn.PERCENTILE.INC($Q$2:$Q$610,0.67),"Medium","High")) -> Low | Z7: =IF(G7<=7,"Met","Not Met") -> Met | AA7: =IF(R7>20%,"High Discount","Low Discount") -> High Discount | AB7: =MIN(R7,ControlPanel!$B$5) -> 0.2 | AC7: =P7*(1+ControlPanel!$B$6) -> 5.775 | AD7: =T7*(1+ControlPanel!$B$7) -> 4.4 | AE7: =(Q7*(100%-AB7)*AD7) -> 20.8384 | AF7: =AE7-(AC7*AD7) -> -4.5716
A8: ORD-2025-541048 | B8: 45751 | C8: =TEXT(B8,"MMM-YYYY") -> Apr-2025 | D8: ="Q" & ROUNDUP(MONTH(B8)/3,0) & "-" & YEAR(B8) -> Q2-2025 | E8: 45760 | F8: =IF(B8>E8,B8+14,E8) -> 45760 | G8: =F8-B8 -> 9 | H8: Europe | I8: Germany | J8: Munich | K8: Consumer | L8: Marketplace | M8: F. Müller | N8: Phones | O8: PHN-3803 | P8: 7.02 | Q8: 6.28 | R8: 0.134 | S8: =IF(R8>30,TRUE) -> FALSE | T8: 14 | U8: =(Q8*(100%-R8))*T8 -> 76.13872 | V8: =P8*T8 -> 98.28 | W8: =U8-V8 -> -22.14128 | X8: =IF(U8=0,0,W8/U8) -> -0.29080184 | Y8: =IF(Q8<=_xlfn.PERCENTILE.INC($Q$2:$Q$610,0.33),"Low",IF(Q8<=_xlfn.PERCENTILE.INC($Q$2:$Q$610,0.67),"Medium","High")) -> Low | Z8: =IF(G8<=7,"Met","Not Met") -> Not Met | AA8: =IF(R8>20%,"High Discount","Low Discount") -> Low Discount | AB8: =MIN(R8,ControlPanel!$B$5) -> 0.134 | AC8: =P8*(1+ControlPanel!$B$6) -> 7.371 | AD8: =T8*(1+ControlPanel!$B$7) -> 15.4 | AE8: =(Q8*(100%-AB8)*AD8) -> 83.752592 | AF8: =AE8-(AC8*AD8) -> -29.760808
A9: ORD-2023-286994 | B9: 44981 | C9: =TEXT(B9,"MMM-YYYY") -> Feb-2023 | D9: ="Q" & ROUNDUP(MONTH(B9)/3,0) & "-" & YEAR(B9) -> Q1-2023 | E9: 44994 | F9: =IF(B9>E9,B9+14,E9) -> 44994 | G9: =F9-B9 -> 13 | H9: Americas | I9: USA | J9: New York | K9: Enterprise | L9: Online | M9: M. Rossi | N9: Components | O9: CMP-1632 | P9: 6.85 | Q9: 10.18 | R9: 0.047 | S9: =IF(R9>30,TRUE) -> FALSE | T9: 10 | U9: =(Q9*(100%-R9))*T9 -> 97.0154 | V9: =P9*T9 -> 68.5 | W9: =U9-V9 -> 28.5154 | X9: =IF(U9=0,0,W9/U9) -> 0.29392653 | Y9: =IF(Q9<=_xlfn.PERCENTILE.INC($Q$2:$Q$610,0.33),"Low",IF(Q9<=_xlfn.PERCENTILE.INC($Q$2:$Q$610,0.67),"Medium","High")) -> Low | Z9: =IF(G9<=7,"Met","Not Met") -> Not Met | AA9: =IF(R9>20%,"High Discount","Low Discount") -> Low Discount | AB9: =MIN(R9,ControlPanel!$B$5) -> 0.047 | AC9: =P9*(1+ControlPanel!$B$6) -> 7.1925 | AD9: =T9*(1+ControlPanel!$B$7) -> 11 | AE9: =(Q9*(100%-AB9)*AD9) -> 106.71694 | AF9: =AE9-(AC9*AD9) -> 27.59944
A10: ORD-2024-516704 | B10: 45352 | C10: =TEXT(B10,"MMM-YYYY") -> Mar-2024 | D10: ="Q" & ROUNDUP(MONTH(B10)/3,0) & "-" & YEAR(B10) -> Q1-2024 | E10: 45351 | F10: =IF(B10>E10,B10+14,E10) -> 45366 | G10: =F10-B10 -> 14 | H10: Americas | I10: Brazil | J10: São Paulo | K10: Non-Profit | L10: Direct | M10: I. Johnson | N10: Phones | O10: PHN-7852 | P10: 5.34 | Q10: 12.69 | R10: 0.132 | S10: =IF(R10>30,TRUE) -> FALSE | T10: 10 | U10: =(Q10*(100%-R10))*T10 -> 110.1492 | V10: =P10*T10 -> 53.4 | W10: =U10-V10 -> 56.7492 | X10: =IF(U10=0,0,W10/U10) -> 0.51520302 | Y10: =IF(Q10<=_xlfn.PERCENTILE.INC($Q$2:$Q$610,0.33),"Low",IF(Q10<=_xlfn.PERCENTILE.INC($Q$2:$Q$610,0.67),"Medium","High")) -> Low | Z10: =IF(G10<=7,"Met","Not Met") -> Not Met | AA10: =IF(R10>20%,"High Discount","Low Discount") -> Low Discount | AB10: =MIN(R10,ControlPanel!$B$5) -> 0.132 | AC10: =P10*(1+ControlPanel!$B$6) -> 5.607 | AD10: =T10*(1+ControlPanel!$B$7) -> 11 | AE10: =(Q10*(100%-AB10)*AD10) -> 121.16412 | AF10: =AE10-(AC10*AD10) -> 59.48712
A11: ORD-2023-251563 | B11: 45057 | C11: =TEXT(B11,"MMM-YYYY") -> May-2023 | D11: ="Q" & ROUNDUP(MONTH(B11)/3,0) & "-" & YEAR(B11) -> Q2-2023 | E11: 45084 | F11: =IF(B11>E11,B11+14,E11) -> 45084 | G11: =F11-B11 -> 27 | H11: Africa | I11: Kenya | J11: Mombasa | K11: Corporate | L11: Online | M11: J. Njeri | N11: Phones | O11: PHN-8970 | P11: 12.85 | Q11: 15.41 | R11: 0.137 | S11: =IF(R11>30,TRUE) -> FALSE | T11: 39 | U11: =(Q11*(100%-R11))*T11 -> 518.65437 | V11: =P11*T11 -> 501.15 | W11: =U11-V11 -> 17.50437 | X11: =IF(U11=0,0,W11/U11) -> 0.033749585 | Y11: =IF(Q11<=_xlfn.PERCENTILE.INC($Q$2:$Q$610,0.33),"Low",IF(Q11<=_xlfn.PERCENTILE.INC($Q$2:$Q$610,0.67),"Medium","High")) -> Low | Z11: =IF(G11<=7,"Met","Not Met") -> Not Met | AA11: =IF(R11>20%,"High Discount","Low Discount") -> Low Discount | AB11: =MIN(R11,ControlPanel!$B$5) -> 0.137 | AC11: =P11*(1+ControlPanel!$B$6) -> 13.4925 | AD11: =T11*(1+ControlPanel!$B$7) -> 42.9 | AE11: =(Q11*(100%-AB11)*AD11) -> 570.51981 | AF11: =AE11-(AC11*AD11) -> -8.308443
A12: ORD-2024-960952 | B12: 45325 | C12: =TEXT(B12,"MMM-YYYY") -> Feb-2024 | D12: ="Q" & ROUNDUP(MONTH(B12)/3,0) & "-" & YEAR(B12) -> Q1-2024 | E12: 45343 | F12: =IF(B12>E12,B12+14,E12) -> 45343 | G12: =F12-B12 -> 18 | H12: Europe | I12: Germany | J12: Frankfurt | K12: Corporate | L12: Retail | M12: H. Kim | N12: Components | O12: CMP-9264 | P12: 39.23 | Q12: 30.09 | R12: 0.177 | S12: =IF(R12>30,TRUE) -> FALSE | T12: 13 | U12: =(Q12*(100%-R12))*T12 -> 321.93291 | V12: =P12*T12 -> 509.99 | W12: =U12-V12 -> -188.05709 | X12: =IF(U12=0,0,W12/U12) -> -0.58414994 | Y12: =IF(Q12<=_xlfn.PERCENTILE.INC($Q$2:$Q$610,0.33),"Low",IF(Q12<=_xlfn.PERCENTILE.INC($Q$2:$Q$610,0.67),"Medium","High")) -> Low | Z12: =IF(G12<=7,"Met","Not Met") -> Not Met | AA12: =IF(R12>20%,"High Discount","Low Discount") -> Low Discount | AB12: =MIN(R12,ControlPanel!$B$5) -> 0.177 | AC12: =P12*(1+ControlPanel!$B$6) -> 41.1915 | AD12: =T12*(1+ControlPanel!$B$7) -> 14.3 | AE12: =(Q12*(100%-AB12)*AD12) -> 354.1262 | AF12: =AE12-(AC12*AD12) -> -234.91225
A13: ORD-2025-946490 | B13: 45769 | C13: =TEXT(B13,"MMM-YYYY") -> Apr-2025 | D13: ="Q" & ROUNDUP(MONTH(B13)/3,0) & "-" & YEAR(B13) -> Q2-2025 | E13: 45779 | F13: =IF(B13>E13,B13+14,E13) -> 45779 | G13: =F13-B13 -> 10 | H13: Europe | I13: Germany | J13: Berlin | K13: Corporate | L13: Marketplace | M13: C. Otieno | N13: Monitors | O13: MON-2842 | P13: 20.15 | Q13: 39.74 | R13: 0.151 | S13: =IF(R13>30,TRUE) -> FALSE | T13: 18 | U13: =(Q13*(100%-R13))*T13 -> 607.30668 | V13: =P13*T13 -> 362.7 | W13: =U13-V13 -> 244.60668 | X13: =IF(U13=0,0,W13/U13) -> 0.40277291 | Y13: =IF(Q13<=_xlfn.PERCENTILE.INC($Q$2:$Q$610,0.33),"Low",IF(Q13<=_xlfn.PERCENTILE.INC($Q$2:$Q$610,0.67),"Medium","High")) -> Low | Z13: =IF(G13<=7,"Met","Not Met") -> Not Met | AA13: =IF(R13>20%,"High Discount","Low Discount") -> Low Discount | AB13: =MIN(R13,ControlPanel!$B$5) -> 0.151 | AC13: =P13*(1+ControlPanel!$B$6) -> 21.1575 | AD13: =T13*(1+ControlPanel!$B$7) -> 19.8 | AE13: =(Q13*(100%-AB13)*AD13) -> 668.03735 | AF13: =AE13-(AC13*AD13) -> 249.11885
A14: ORD-2023-235230 | B14: 45168 | C14: =TEXT(B14,"MMM-YYYY") -> Aug-2023 | D14: ="Q" & ROUNDUP(MONTH(B14)/3,0) & "-" & YEAR(B14) -> Q3-2023 | E14: 45170 | F14: =IF(B14>E14,B14+14,E14) -> 45170 | G14: =F14-B14 -> 2 | H14: Europe | I14: Germany | J14: Munich | K14: Corporate | L14: Direct | M14: N. Brown | N14: Networking | O14: NET-9989 | P14: 44.42 | Q14: 41.9 | R14: 0.144 | S14: =IF(R14>30,TRUE) -> FALSE | T14: 6 | U14: =(Q14*(100%-R14))*T14 -> 215.1984 | V14: =P14*T14 -> 266.52 | W14: =U14-V14 -> -51.3216 | X14: =IF(U14=0,0,W14/U14) -> -0.23848504 | Y14: =IF(Q14<=_xlfn.PERCENTILE.INC($Q$2:$Q$610,0.33),"Low",IF(Q14<=_xlfn.PERCENTILE.INC($Q$2:$Q$610,0.67),"Medium","High")) -> Low | Z14: =IF(G14<=7,"Met","Not Met") -> Met | AA14: =IF(R14>20%,"High Discount","Low Discount") -> Low Discount | AB14: =MIN(R14,ControlPanel!$B$5) -> 0.144 | AC14: =P14*(1+ControlPanel!$B$6) -> 46.641 | AD14: =T14*(1+ControlPanel!$B$7) -> 6.6 | AE14: =(Q14*(100%-AB14)*AD14) -> 236.71824 | AF14: =AE14-(AC14*AD14) -> -71.11236
A15: ORD-2023-835226 | B15: 45225 | C15: =TEXT(B15,"MMM-YYYY") -> Oct-2023 | D15: ="Q" & ROUNDUP(MONTH(B15)/3,0) & "-" & YEAR(B15) -> Q4-2023 | E15: 45235 | F15: =IF(B15>E15,B15+14,E15) -> 45235 | G15: =F15-B15 -> 10 | H15: Africa | I15: South Africa | J15: Cape Town | K15: Non-Profit | L15: Online | M15: I. Johnson | N15: Laptops | O15: LAP-7320 | P15: 20.38 | Q15: 42.56 | R15: 0.072 | S15: =IF(R15>30,TRUE) -> FALSE | T15: 11 | U15: =(Q15*(100%-R15))*T15 -> 434.45248 | V15: =P15*T15 -> 224.18 | W15: =U15-V15 -> 210.27248 | X15: =IF(U15=0,0,W15/U15) -> 0.4839942 | Y15: =IF(Q15<=_xlfn.PERCENTILE.INC($Q$2:$Q$610,0.33),"Low",IF(Q15<=_xlfn.PERCENTILE.INC($Q$2:$Q$610,0.67),"Medium","High")) -> Low | Z15: =IF(G15<=7,"Met","Not Met") -> Not Met | AA15: =IF(R15>20%,"High Discount","Low Discount") -> Low Discount | AB15: =MIN(R15,ControlPanel!$B$5) -> 0.072 | AC15: =P15*(1+ControlPanel!$B$6) -> 21.399 | AD15: =T15*(1+ControlPanel!$B$7) -> 12.1 | AE15: =(Q15*(100%-AB15)*AD15) -> 477.89773 | AF15: =AE15-(AC15*AD15) -> 218.96983
A16: ORD-2025-488349 | B16: 45770 | C16: =TEXT(B16,"MMM-YYYY") -> Apr-2025 | D16: ="Q" & ROUNDUP(MONTH(B16)/3,0) & "-" & YEAR(B16) -> Q2-2025 | E16: 45769 | F16: =IF(B16>E16,B16+14,E16) -> 45784 | G16: =F16-B16 -> 14 | H16: Americas | I16: USA | J16: San Francisco | K16: Non-Profit | L16: Distributor | M16: D. Smith | N16: Monitors | O16: MON-3371 | P16: 23.24 | Q16: 44.57 | R16: 0.215 | S16: =IF(R16>30,TRUE) -> FALSE | T16: 15 | U16: =(Q16*(100%-R16))*T16 -> 524.81175 | V16: =P16*T16 -> 348.6 | W16: =U16-V16 -> 176.21175 | X16: =IF(U16=0,0,W16/U16) -> 0.33576182 | Y16: =IF(Q16<=_xlfn.PERCENTILE.INC($Q$2:$Q$610,0.33),"Low",IF(Q16<=_xlfn.PERCENTILE.INC($Q$2:$Q$610,0.67),"Medium","High")) -> Low | Z16: =IF(G16<=7,"Met","Not Met") -> Not Met | AA16: =IF(R16>20%,"High Discount","Low Discount") -> High Discount | AB16: =MIN(R16,ControlPanel!$B$5) -> 0.2 | AC16: =P16*(1+ControlPanel!$B$6) -> 24.402 | AD16: =T16*(1+ControlPanel!$B$7) -> 16.5 | AE16: =(Q16*(100%-AB16)*AD16) -> 588.324 | AF16: =AE16-(AC16*AD16) -> 185.691
... A610: ORD-2024-798002 | B610: 45498 | C610: =TEXT(B610,"MMM-YYYY") -> Jul-2024 | D610: ="Q" & ROUNDUP(MONTH(B610)/3,0) & "-" & YEAR(B610) -> Q3-2024 | E610: 45497 | F610: =IF(B610>E610,B610+14,E610) -> 45512 | G610: =F610-B610 -> 14 | H610: Africa | I610: Kenya | J610: Mombasa | K610: Non-Profit | L610: Direct | M610: J. Njeri | N610: Laptops | O610: LAP-9815 | P610: 1494.4 | Q610: 3661.07 | R610: 0.072 | S610: =IF(R610>30,TRUE) -> FALSE | T610: 7 | U610: =(Q610*(100%-R610))*T610 -> 23782.311 | V610: =P610*T610 -> 10460.8 | W610: =U610-V610 -> 13321.511 | X610: =IF(U610=0,0,W610/U610) -> 0.56014367 | Y610: =IF(Q610<=_xlfn.PERCENTILE.INC($Q$2:$Q$610,0.33),"Low",IF(Q610<=_xlfn.PERCENTILE.INC($Q$2:$Q$610,0.67),"Medium","High")) -> High | Z610: =IF(G610<=7,"Met","Not Met") -> Not Met | AA610: =IF(R610>20%,"High Discount","Low Discount") -> Low Discount | AB610: =MIN(R610,ControlPanel!$B$5) -> 0.072 | AC610: =P610*(1+ControlPanel!$B$6) -> 1569.12 | AD610: =T610*(1+ControlPanel!$B$7) -> 7.7 | AE610: =(Q610*(100%-AB610)*AD610) -> 26160.542 | AF610: =AE610-(AC610*AD610) -> 14078.318
A613: Average OrderValue | B613: =SUM(U2:U610)/COUNTA(A2:A610) -> 17441.686

Sheet Brief
A2: Excel Mastery Assignment: Sales Operations & Analytics
A4: Overview:
A5: You are an analyst for a multi-regional electronics distributor. The 'Data' sheet contains 632 rows and 15 columns of transactional data with intentional data-quality issues.
A6: Your job is to clean, enrich, analyze, and present insights via a dynamic dashboard.
A8: Part A — Data Cleaning & Preparation:
A9: 1) Create a staging table where you:
A10: • Remove exact duplicate rows (define and document your duplicate criteria).
A11: • Fix data types (dates as Dates, numeric fields as numbers).
A12: • Handle missing values for City, Salesperson, and Channel using reasonable business logic (document your approach).
A13: • Flag and correct suspicious UnitPrice values (e.g., negative prices) and discounts (e.g., > 30%).
A14: • Ensure RequiredDate is not earlier than OrderDate; where it is, impute a corrected RequiredDate (explain your rule).
A15: • Add a derived 'LeadTimeDays' = RequiredDate − OrderDate (in days).
... A67: 15) Ensure your dashboard responds to slicers without broken references.

Sheet Dashboard

Sheet Insights
A1: Insights from Dashboard
A2: Overall business performance remained profitable, generating $10.62M in revenue and $3.39M in profit, with a healthy 24.55% profit margin, indicating that pricing and cost management remained effective despite varying sales performance.
A3: Revenue followed a clear seasonal pattern. Sales climbed steadily from January, peaked during May–July, then declined sharply in September–November before recovering slightly in December, suggesting opportunities to strengthen promotions during weaker months.
A4: Africa delivered consistent mid-range profitability across its salespeople. While it did not produce the highest individual performer, the relatively balanced results indicate stable sales execution with room to grow through targeted campaigns.
A5: The Americas showed the widest variation in salesperson performance, with some of the strongest contributors alongside lower-performing representatives. This suggests that sharing best practices from top performers could significantly lift regional results.
A6: Asia maintained steady profit generation without extreme highs or lows. The region appears dependable, making it a strong candidate for incremental investment to increase revenue while maintaining stable margins.
A7: Europe emerged as the strongest-performing region, recording the highest individual salesperson profit on the dashboard. Expanding successful sales strategies used in Europe could help improve performance in other regions.
A8: Revenue is concentrated among a small number of SKUs. Products such as CMP-8851 and NBK-2565 generated substantially more revenue than the remaining SKUs, highlighting the importance of protecting inventory and marketing support for these top-selling products while improving the performance of lower-selling SKUs.
A9: Discounting appears well controlled overall. The discount outlier analysis shows most transactions clustered within a relatively narrow range, with only a few high-discount exceptions. Monitoring these outliers can help prevent unnecessary margin erosion while maintaining competitive pricing.

Sheet Documentation
A1: 1 | B1: Data Cleaning & Preparation
B2: Removed duplicate records using Excel's Remove duplicates feature.One duplicate Order ID was identified and removed,resulting in 632 unique records.
B3: Converted the Order Date and Required Date columns to Short Date format.
B4: Changed the Unit Cost, Unit Price, and Quantity columns to the Number data type and formatted Discount Percentage as Percentage.
B5: Filtered the City column and removed 8 records with missing values.
B6: Filtered the Channel column and removed 7 records with missing values.
B7: Filtered the Salesperson column and removed 7 records with missing values.
A8: 2 | B8: Data Validation
B9: Sorted the Unit Price column in ascending order to identify pricing anomalies and found 3 records with negative values.
B10: Recalculated the affected Unit Prices by deriving the selling price before discount using:
B11: Selling Price = (Unit Cost × Quantity) ÷ (1 − Discount %)
B12: The corrected Unit Price was then calculated by dividing the selling price by the quantity.
B13: Used an IF formula to identify discount values greater than 30%.
B14: Compared Unit Price with Unit Cost for these records and corrected invalid discounts to 0% where no genuine discount existed.
B15: Used an IF formula to identify records where Required Date occurred before Order Date and corrected the Required Date to match the Order Date.
A16: 3 | B16: Feature Engineering
B17: Created a Lead Time (Days) column by calculating the difference between Required Date and Order Date.
B18: Created the following calculated business metrics:
B19: Gross Revenue = Unit Price × Quantity × (1 − Discount %)
B20: Cost of Goods = Unit Cost × Quantity
B21: Gross Profit = Gross Revenue − Cost of Goods
B22: Profit Margin (%) = Gross Profit ÷ Gross Revenue
A23: 4 | B23: Time Intelligence
B24: Created a Month column using the TEXT function in the format Month Year
B25: Created a Quarter column by combining the quarter number (derived from the month) with the year
A26: 5 | B26: Data Categorisation
B27: Verified that the Region Hierarchy was already available in the dataset.
B28: Created a Price Band column using the IF and PERCENTILE.INC functions to classify products into Low, Medium, and High price categories.

Sheet SalesProductivity
A3: Row Labels | B3: Sum of GrossRevenue | C3: Sum of Gross Profit
A4: M. Rossi | B4: 986812.79 | C4: 324975.39
A5: B. Chen | B5: 835463.29 | C5: 304232.76
A6: L. Okafor | B6: 856334.38 | C6: 273012.41
A7: J. Njeri | B7: 792518.35 | C7: 269095.99
A8: K. Singh | B8: 856189.24 | C8: 266525.14
A9: C. Otieno | B9: 711548.87 | C9: 260610.21
A10: A. Patel | B10: 812078.77 | C10: 255082.63
A11: F. Müller | B11: 812637.17 | C11: 251733.01
A12: E. Garcia | B12: 539014.49 | C12: 203717.83
A13: H. Kim | B13: 742300.56 | C13: 197356.1
A14: O. Wang | B14: 647577.89 | C14: 185219.07
A15: G. Dubois | B15: 508766.72 | C15: 172033.5
... A19: Grand Total | B19: 10621987 | C19: 3386709.2

Sheet AvgOrdVal
A3: Row Labels | B3: Sum of GrossRevenue
A4: ORD-2023-107265 | B4: 13856.524
A5: ORD-2023-109927 | B5: 12462.651
A6: ORD-2023-112666 | B6: 685.06776
A7: ORD-2023-125739 | B7: 855.72882
A8: ORD-2023-126505 | B8: 14466.951
A9: ORD-2023-128295 | B9: 7135.57
A10: ORD-2023-132101 | B10: 13784.586
A11: ORD-2023-133848 | B11: 25299.04
A12: ORD-2023-139236 | B12: 18830.125
A13: ORD-2023-144816 | B13: 9829.0483
A14: ORD-2023-156396 | B14: 2795.6384
A15: ORD-2023-157993 | B15: 14448.299
... A613: Grand Total | B613: 10621987
B615: =AVERAGE(B4:B612) -> 17441.686

Sheet GrossRevenueBYSKUsChart
A1: Row Labels | B1: Sum of GrossRevenue
A2: CMP-8851 | B2: 139277.83
A3: NET-2365 | B3: 109244
A4: MON-6962 | B4: 92715.25
A5: MON-2266 | B5: 87404.93
A6: MON-6699 | B6: 85637.74
A7: CMP-3938 | B7: 84136.12
A8: LAP-3904 | B8: 82514.712
A9: NET-5987 | B9: 82141.34
A10: NET-5523 | B10: 79548.756
A11: ACC-6626 | B11: 79082.507
A12: Grand Total | B12: 921703.18

Sheet ProfitByRegionChart
A1: Row Labels | B1: Sum of Gross Profit
A2: Africa | B2: 805163.54
A3: Direct | B3: 192186.25
A4: Distributor | B4: 216522.74
A5: Marketplace | B5: 143876.28
A6: Online | B6: 98489.604
A7: Retail | B7: 154088.67
A8: Americas | B8: 819948.14
A9: Direct | B9: 256317.67
A10: Distributor | B10: 153307.1
A11: Marketplace | B11: 96609.648
A12: Online | B12: 244678.02
A13: Retail | B13: 69035.709
... A26: Grand Total | B26: 3386709.2

Sheet RevenueByMonthChart
A1: Row Labels | B1: Sum of GrossRevenue
A2: Jan | B2: 652290.27
A3: Feb | B3: 937572.48
A4: Mar | B4: 804287.24
A5: Apr | B5: 927284.73
A6: May | B6: 1267781.5
A7: Jun | B7: 1242729.2
A8: Jul | B8: 1207001.4
A9: Aug | B9: 1053213.3
A10: Sep | B10: 629646.34
A11: Oct | B11: 673055.51
A12: Nov | B12: 502327.83
A13: Dec | B13: 724796.97
A14: Grand Total | B14: 10621987

Sheet Scenario Summary
B2: Scenario Summary
D3: Current Values: | E3: Best Case Scenario | F3: Worst Case Scenario | G3: Base Case Scenario
E4: Created by user on 8/3/2026 | F4: Created by user on 8/3/2026 | G4: Created by user on 8/3/2026
B5: Changing Cells:
C6: $B$5 | D6: 0.2 | E6: 0.1 | F6: 0.25 | G6: 0.2
C7: $B$6 | D7: 0.05 | E7: 0 | F7: 0.15 | G7: 0.05
C8: $B$7 | D8: 0.1 | E8: 0.2 | F8: 0 | G8: 0.1
B9: Result Cells:
C10: $B$5 | D10: 0.2 | E10: 0.1 | F10: 0.25 | G10: 0.2
C11: $B$6 | D11: 0.05 | E11: 0 | F11: 0.15 | G11: 0.05
C12: $B$7 | D12: 0.1 | E12: 0.2 | F12: 0 | G12: 0.1
B13: Notes: Current Values column represents values of changing cells at
B14: time Scenario Summary Report was created. Changing cells for each
B15: scenario are highlighted in gray.

Sheet ControlPanel
A3: What If Analysis
A4: A | B4: B
A5: Global Discount Cap | B5: 0.2
A6: Unit Cost Inflation | B6: 0.05
A7: Quantity Uplift | B7: 0.1
A8: Total Scenario Revenue | B8: =SUM('Staging Table'!AE2:AE610) -> 11751007
A9: Total Scenario Profit | B9: =SUM('Staging Table'!AF2:AF610) -> 3394261.5

Sheet Price Compliance
A3: Count of Disc>20 | B3: Column Labels
A4: Row Labels | B4: Africa | C4: Americas | D4: Asia | E4: Europe | F4: Grand Total
A5: A. Patel | B5: 0.026272578 | C5: 0.013136289 | D5: 0.016420361 | E5: 0.016420361 | F5: 0.072249589
A6: B. Chen | B6: 0.013136289 | C6: 0.013136289 | D6: 0.024630542 | E6: 0.024630542 | F6: 0.075533662
A7: C. Otieno | B7: 0.013136289 | C7: 0.02134647 | D7: 0.016420361 | E7: 0.0082101806 | F7: 0.0591133
A8: D. Smith | B8: 0.016420361 | C8: 0.013136289 | D8: 0.013136289 | E8: 0.016420361 | F8: 0.0591133
A9: E. Garcia | B9: 0.0082101806 | C9: 0.0082101806 | D9: 0.013136289 | E9: 0.024630542 | F9: 0.054187192
A10: F. Müller | B10: 0.02134647 | C10: 0.024630542 | D10: 0.019704433 | E10: 0.018062397 | F10: 0.083743842
A11: G. Dubois | B11: 0.0032840722 | C11: 0.013136289 | D11: 0.018062397 | E11: 0.013136289 | F11: 0.047619048
A12: H. Kim | B12: 0.0098522167 | C12: 0.014778325 | D12: 0.024630542 | E12: 0.02134647 | F12: 0.070607553
A13: I. Johnson | B13: 0.013136289 | C13: 0.022988506 | D13: 0.013136289 | E13: 0.013136289 | F13: 0.062397373
A14: J. Njeri | B14: 0.019704433 | C14: 0.016420361 | D14: 0.02955665 | E14: 0.014778325 | F14: 0.08045977
A15: K. Singh | B15: 0.02134647 | C15: 0.016420361 | D15: 0.011494253 | E15: 0.02134647 | F15: 0.070607553
A16: L. Okafor | B16: 0.016420361 | C16: 0.019704433 | D16: 0.022988506 | E16: 0.016420361 | F16: 0.075533662
... A20: Grand Total | B20: 0.22824302 | C20: 0.24794745 | D20: 0.26765189 | E20: 0.25615764 | F20: 1

Sheet ChannelMix&Cannibalization
A3: Sum of GrossRevenue | B3: Column Labels
A4: Row Labels | B4: Africa | C4: Americas | D4: Asia | E4: Europe | F4: Grand Total
A5: Direct | B5: 475695.39 | C5: 743701.63 | D5: 648332.15 | E5: 803097.65 | F5: 2670826.8
A6: Distributor | B6: 648374.5 | C6: 496759.7 | D6: 508677.37 | E6: 318736.67 | F6: 1972548.2
A7: Marketplace | B7: 474202.37 | C7: 366375.93 | D7: 572278.53 | E7: 628123.38 | F7: 2040980.2
A8: Online | B8: 331283.39 | C8: 654555.18 | D8: 396301.7 | E8: 585406.72 | F8: 1967547
A9: Retail | B9: 531639.22 | C9: 302853.58 | D9: 653613 | E9: 481978.67 | F9: 1970084.5
A10: Grand Total | B10: 2461194.9 | C10: 2564246 | D10: 2779202.8 | E10: 2817343.1 | F10: 10621987

Sheet ServiceLevelProxy
A3: Count of Met Target | B3: Column Labels
A4: Row Labels | B4: Met | C4: Not Met | D4: Grand Total
A5: Brazil | B5: 0.019704433 | C5: 0.075533662 | D5: 0.095238095
A6: Canada | B6: 0.0098522167 | C6: 0.060755337 | D6: 0.070607553
A7: China | B7: 0.014778325 | C7: 0.065681445 | D7: 0.08045977
A8: France | B8: 0.019704433 | C8: 0.067323481 | D8: 0.087027915
A9: Germany | B9: 0.018062397 | C9: 0.065681445 | D9: 0.083743842
A10: India | B10: 0.018062397 | C10: 0.075533662 | D10: 0.093596059
A11: Japan | B11: 0.016420361 | C11: 0.077175698 | D11: 0.093596059
A12: Kenya | B12: 0.024630542 | C12: 0.065681445 | D12: 0.090311987
A13: Nigeria | B13: 0.02134647 | C13: 0.047619048 | D13: 0.068965517
A14: South Africa | B14: 0.013136289 | C14: 0.055829228 | D14: 0.068965517
A15: United Kingdom | B15: 0.02134647 | C15: 0.064039409 | D15: 0.085385878
A16: USA | B16: 0.022988506 | C16: 0.0591133 | D16: 0.082101806
A17: Grand Total | B17: 0.22003284 | C17: 0.77996716 | D17: 1

Sheet Cohort Analysis
A3: Sum of GrossRevenue | B3: Column Labels
B4: 2023 | C4: 2024 | D4: 2025 | E4: Grand Total
A6: Row Labels
A7: Brazil | B7: 361577.36 | C7: 232258.25 | D7: 357205.44 | E7: 951041.06
A8: Canada | B8: 249507.27 | C8: 327555.68 | D8: 276703.56 | E8: 853766.5
A9: China | B9: 295037.38 | C9: 431317.1 | D9: 184532.59 | E9: 910887.07
A10: France | B10: 269344.22 | C10: 332686.45 | D10: 209865.14 | E10: 811895.82
A11: Germany | B11: 369878.67 | C11: 383309.25 | D11: 176236.96 | E11: 929424.89
A12: India | B12: 456495.73 | C12: 374020.28 | D12: 207129.62 | E12: 1037645.6
A13: Japan | B13: 183693.53 | C13: 353042.14 | D13: 293934.4 | E13: 830670.07
A14: Kenya | B14: 275192.36 | C14: 563786.7 | D14: 144878.39 | E14: 983857.45
A15: Nigeria | B15: 236085.65 | C15: 276445.2 | D15: 240025.99 | E15: 752556.84
A16: South Africa | B16: 340606.41 | C16: 191518.51 | D16: 192655.66 | E16: 724780.58
A17: United Kingdom | B17: 276400.41 | C17: 510158.48 | D17: 289463.5 | E17: 1076022.4
A18: USA | B18: 288079.89 | C18: 387432.32 | D18: 83926.237 | E18: 759438.45
A19: Grand Total | B19: 3601898.9 | C19: 4363530.4 | D19: 2656557.5 | E19: 10621987

Sheet ABCAnalysisPivotTable
A3: Row Labels | B3: Sum of GrossRevenue
A4: Accessories | B4: 1311026.9
A5: Components | B5: 1545849.3 | I5: =AVERAGE('Staging Table'!X2:X610) -> 0.24546923
A6: Laptops | B6: 1595752.9
A7: LAP-3904 | B7: 82514.712
A8: LAP-8214 | B8: 65119.33
A9: LAP-5763 | B9: 65066.934
A10: LAP-6499 | B10: 64192.977
A11: LAP-1739 | B11: 58526.831
A12: LAP-8825 | B12: 58057.65
A13: LAP-7523 | B13: 44173.628
A14: LAP-1308 | B14: 42433.254
A15: LAP-1178 | B15: 41914.216
A16: LAP-4483 | B16: 40563.322
A17: LAP-3490 | B17: 40139.875
... A446: Grand Total | B446: 10621987

Sheet ABC_Analysis
A1: Row Labels | B1: Sum of GrossRevenue | C1: Revenue% | D1: Cumulative revenue(%) | E1: ABC
A3: Accessories | B3: 1311026.9
A4: ACC-6626 | B4: 79082.507 | C4: =B4/$B$3 -> 0.060321043 | D4: =C4 -> 0.060321043 | E4: =IF(D4<=80%,"A",IF(D4<=95%,"B","C")) -> A
A5: ACC-1770 | B5: 58719.833 | C5: =B5/$B$3 -> 0.044789191 | D5: =D4+C5 -> 0.10511023 | E5: =IF(D5<=80%,"A",IF(D5<=95%,"B","C")) -> A
A6: ACC-2988 | B6: 53034.364 | C6: =B6/$B$3 -> 0.040452538 | D6: =D5+C6 -> 0.14556277 | E6: =IF(D6<=80%,"A",IF(D6<=95%,"B","C")) -> A
A7: ACC-9283 | B7: 46450.26 | C7: =B7/$B$3 -> 0.035430441 | D7: =D6+C7 -> 0.18099321 | E7: =IF(D7<=80%,"A",IF(D7<=95%,"B","C")) -> A
A8: ACC-9533 | B8: 43084.872 | C8: =B8/$B$3 -> 0.032863455 | D8: =D7+C8 -> 0.21385667 | E8: =IF(D8<=80%,"A",IF(D8<=95%,"B","C")) -> A
A9: ACC-1238 | B9: 39236.64 | C9: =B9/$B$3 -> 0.029928174 | D9: =D8+C9 -> 0.24378484 | E9: =IF(D9<=80%,"A",IF(D9<=95%,"B","C")) -> A
A10: ACC-8098 | B10: 38096.184 | C10: =B10/$B$3 -> 0.029058279 | D10: =D9+C10 -> 0.27284312 | E10: =IF(D10<=80%,"A",IF(D10<=95%,"B","C")) -> A
A11: ACC-7838 | B11: 35167.745 | C11: =B11/$B$3 -> 0.02682458 | D11: =D10+C11 -> 0.2996677 | E11: =IF(D11<=80%,"A",IF(D11<=95%,"B","C")) -> A
A12: ACC-5177 | B12: 34139.16 | C12: =B12/$B$3 -> 0.026040016 | D12: =D11+C12 -> 0.32570772 | E12: =IF(D12<=80%,"A",IF(D12<=95%,"B","C")) -> A
A13: ACC-9162 | B13: 33062.236 | C13: =B13/$B$3 -> 0.025218581 | D13: =D12+C13 -> 0.3509263 | E13: =IF(D13<=80%,"A",IF(D13<=95%,"B","C")) -> A
A14: ACC-7078 | B14: 32086.376 | C14: =B14/$B$3 -> 0.024474232 | D14: =D13+C14 -> 0.37540053 | E14: =IF(D14<=80%,"A",IF(D14<=95%,"B","C")) -> A
A15: ACC-1659 | B15: 28386.016 | C15: =B15/$B$3 -> 0.021651743 | D15: =D14+C15 -> 0.39705227 | E15: =IF(D15<=80%,"A",IF(D15<=95%,"B","C")) -> A
A16: ACC-6223 | B16: 26765.04 | C16: =B16/$B$3 -> 0.020415326 | D16: =D15+C16 -> 0.4174676 | E16: =IF(D16<=80%,"A",IF(D16<=95%,"B","C")) -> A
... A87: ACC-6777 | B87: 18.65984 | C87: =B87/$B$3 -> 1.4232996e-05 | D87: =D86+C87 -> 1 | E87: =IF(D87<=80%,"A",IF(D87<=95%,"B","C")) -> C
A88: Components | B88: 1545849.3
A89: CMP-8851 | B89: 139277.83 | C89: =B89/$B$88 -> 0.090097934 | D89: =C89 -> 0.090097934 | E89: =IF(D89<=80%,"A",IF(D89<=95%,"B","C")) -> A
A90: CMP-3938 | B90: 84136.12 | C90: =B90/$B$88 -> 0.054427115 | D90: =D89+C90 -> 0.14452505 | E90: =IF(D90<=80%,"A",IF(D90<=95%,"B","C")) -> A
A91: CMP-2096 | B91: 74802.35 | C91: =B91/$B$88 -> 0.04838916 | D91: =D90+C91 -> 0.19291421 | E91: =IF(D91<=80%,"A",IF(D91<=95%,"B","C")) -> A
A92: CMP-2040 | B92: 65111.386 | C92: =B92/$B$88 -> 0.042120137 | D92: =D91+C92 -> 0.23503435 | E92: =IF(D92<=80%,"A",IF(D92<=95%,"B","C")) -> A
A93: CMP-3731 | B93: 60928.502 | C93: =B93/$B$88 -> 0.039414257 | D93: =D92+C93 -> 0.2744486 | E93: =IF(D93<=80%,"A",IF(D93<=95%,"B","C")) -> A
A94: CMP-8127 | B94: 50296.415 | C94: =B94/$B$88 -> 0.032536428 | D94: =D93+C94 -> 0.30698503 | E94: =IF(D94<=80%,"A",IF(D94<=95%,"B","C")) -> A
A95: CMP-5006 | B95: 41419.524 | C95: =B95/$B$88 -> 0.026794024 | D95: =D94+C95 -> 0.33377905 | E95: =IF(D95<=80%,"A",IF(D95<=95%,"B","C")) -> A
A96: CMP-1940 | B96: 40476.013 | C96: =B96/$B$88 -> 0.026183673 | D96: =D95+C96 -> 0.35996273 | E96: =IF(D96<=80%,"A",IF(D96<=95%,"B","C")) -> A
A97: CMP-8002 | B97: 33687.502 | C97: =B97/$B$88 -> 0.021792229 | D97: =D96+C97 -> 0.38175496 | E97: =IF(D97<=80%,"A",IF(D97<=95%,"B","C")) -> A
A98: CMP-1156 | B98: 33308.55 | C98: =B98/$B$88 -> 0.021547087 | D98: =D97+C98 -> 0.40330204 | E98: =IF(D98<=80%,"A",IF(D98<=95%,"B","C")) -> A
A99: CMP-6529 | B99: 32335.218 | C99: =B99/$B$88 -> 0.020917445 | D99: =D98+C99 -> 0.42421949 | E99: =IF(D99<=80%,"A",IF(D99<=95%,"B","C")) -> A
A100: CMP-6971 | B100: 27701.57 | C100: =B100/$B$88 -> 0.017919968 | D100: =D99+C100 -> 0.44213946 | E100: =IF(D100<=80%,"A",IF(D100<=95%,"B","C")) -> A
A101: CMP-6392 | B101: 27676.35 | C101: =B101/$B$88 -> 0.017903653 | D101: =D100+C101 -> 0.46004311 | E101: =IF(D101<=80%,"A",IF(D101<=95%,"B","C")) -> A
... A176: CMP-1632 | B176: 97.0154 | C176: =B176/$B$88 -> 6.2758639e-05 | D176: =D175+C176 -> 1 | E176: =IF(D176<=80%,"A",IF(D176<=95%,"B","C")) -> C
A177: Laptops | B177: 1595752.9
A178: LAP-3904 | B178: 82514.712 | C178: =B178/$B$177 -> 0.051708952 | D178: =D177+C178 -> 0.051708952 | E178: =IF(D178<=80%,"A",IF(D178<=95%,"B","C")) -> A
A179: LAP-8214 | B179: 65119.33 | C179: =B179/$B$177 -> 0.040807902 | D179: =D178+C179 -> 0.092516854 | E179: =IF(D179<=80%,"A",IF(D179<=95%,"B","C")) -> A
A180: LAP-5763 | B180: 65066.934 | C180: =B180/$B$177 -> 0.040775068 | D180: =D179+C180 -> 0.13329192 | E180: =IF(D180<=80%,"A",IF(D180<=95%,"B","C")) -> A
A181: LAP-6499 | B181: 64192.977 | C181: =B181/$B$177 -> 0.040227391 | D181: =D180+C181 -> 0.17351931 | E181: =IF(D181<=80%,"A",IF(D181<=95%,"B","C")) -> A
A182: LAP-1739 | B182: 58526.831 | C182: =B182/$B$177 -> 0.036676625 | D182: =D181+C182 -> 0.21019594 | E182: =IF(D182<=80%,"A",IF(D182<=95%,"B","C")) -> A
A183: LAP-8825 | B183: 58057.65 | C183: =B183/$B$177 -> 0.036382606 | D183: =D182+C183 -> 0.24657854 | E183: =IF(D183<=80%,"A",IF(D183<=95%,"B","C")) -> A
A184: LAP-7523 | B184: 44173.628 | C184: =B184/$B$177 -> 0.027681997 | D184: =D183+C184 -> 0.27426054 | E184: =IF(D184<=80%,"A",IF(D184<=95%,"B","C")) -> A
A185: LAP-1308 | B185: 42433.254 | C185: =B185/$B$177 -> 0.026591369 | D185: =D184+C185 -> 0.30085191 | E185: =IF(D185<=80%,"A",IF(D185<=95%,"B","C")) -> A
...
